<?xml version="1.0" ?>
<!-- =================================================================================== -->
<!-- |    This document was autogenerated by xacro from medibot.urdf.xacro             | -->
<!-- |    EDITING THIS FILE BY HAND IS NOT RECOMMENDED                                 | -->
<!-- =================================================================================== -->
<robot name="medibot">
  <material name="blue">
    <color rgba="0 0 0.5 1"/>
  </material>
  <material name="grey">
    <color rgba="0.5 0.5 0.5 1"/>
  </material>
  <material name="yellow">
    <color rgba="1 1 0.5 1"/>
  </material>
  <material name="orange">
    <color rgba="1.0 0.65 0.0 1.0"/>
  </material>
  <material name="purple">
    <color rgba="0.5 0 1 1"/>
  </material>
  <!-- upper body link -->
  <link name="body_base_link">
    <visual>
      <geometry>
        <cylinder length="0.5" radius="0.1"/>
      </geometry>
      <origin rpy="0 0 0" xyz="0 0 0"/>
      <material name="purple"/>
    </visual>
    <collision>
      <geometry>
        <cylinder length="0.5" radius="0.1"/>
      </geometry>
      <origin rpy="0 0 0" xyz="0 0 0"/>
    </collision>
    <inertial>
      <origin rpy="0 0 0" xyz="0 0 0"/>
      <mass value="0.5"/>
      <inertia ixx="0.011666666666666667" ixy="0.0" ixz="0.0" iyy="0.011666666666666667" iyz="0.0" izz="0.0025000000000000005"/>
    </inertial>
  </link>
  <!-- shoulder link -->
  <link name="shoulder_link">
    <visual>
      <geometry>
        <box size="0.1 0.6 0.2"/>
      </geometry>
      <origin rpy="0 0 0" xyz="0 0.0 0"/>
      <material name="blue"/>
    </visual>
    <collision>
      <geometry>
        <box size="0.1 0.6 0.2"/>
      </geometry>
      <origin rpy="0 0 0" xyz="0 0.0 0"/>
    </collision>
    <inertial>
      <origin rpy="0 0 0" xyz="0 0 0"/>
      <mass value="10.0"/>
      <inertia ixx="0.04166666666666668" ixy="0.0" ixz="0.0" iyy="0.30833333333333335" iyz="0.0" izz="0.33333333333333337"/>
    </inertial>
  </link>
  <!-- head link -->
  <link name="head_link">
    <visual>
      <geometry>
        <sphere radius="0.1"/>
      </geometry>
      <origin rpy="0 0 0" xyz="0 0 0"/>
      <material name="grey"/>
    </visual>
    <collision>
      <geometry>
        <sphere radius="0.1"/>
      </geometry>
      <origin rpy="0 0 0" xyz="0 0 0"/>
    </collision>
    <inertial>
      <origin rpy="0 0 0" xyz="0 0 0"/>
      <mass value="0.5"/>
      <inertia ixx="0.0020000000000000005" ixy="0.0" ixz="0.0" iyy="0.0020000000000000005" iyz="0.0" izz="0.0020000000000000005"/>
    </inertial>
  </link>
  <!-- right hand link -->
  <link name="right_hand_link">
    <visual>
      <geometry>
        <cylinder length="0.4" radius="0.05"/>
      </geometry>
      <origin rpy="0 0 0" xyz="0 0 0.2"/>
      <material name="grey"/>
    </visual>
    <collision>
      <geometry>
        <cylinder length="0.4" radius="0.05"/>
      </geometry>
      <origin rpy="0 0 0" xyz="0 0 0.2"/>
    </collision>
    <inertial>
      <origin rpy="0 0 0" xyz="0 0 0"/>
      <mass value="0.5"/>
      <inertia ixx="0.006979166666666668" ixy="0.0" ixz="0.0" iyy="0.006979166666666668" iyz="0.0" izz="0.0006250000000000001"/>
    </inertial>
  </link>
  <!-- right arm link -->
  <link name="right_arm_link">
    <visual>
      <geometry>
        <cylinder length="0.5" radius="0.05"/>
      </geometry>
      <origin rpy="0 0 0" xyz="0 0 0.25"/>
      <material name="grey"/>
    </visual>
    <collision>
      <geometry>
        <cylinder length="0.5" radius="0.05"/>
      </geometry>
      <origin rpy="0 0 0" xyz="0 0 0.25"/>
    </collision>
    <inertial>
      <origin rpy="0 0 0" xyz="0 0 0"/>
      <mass value="0.5"/>
      <inertia ixx="0.006979166666666668" ixy="0.0" ixz="0.0" iyy="0.006979166666666668" iyz="0.0" izz="0.0006250000000000001"/>
    </inertial>
  </link>
  <!-- left hand link -->
  <link name="left_hand_link">
    <visual>
      <geometry>
        <cylinder length="0.4" radius="0.05"/>
      </geometry>
      <origin rpy="0 0 0" xyz="0 0 0.2"/>
      <material name="grey"/>
    </visual>
    <collision>
      <geometry>
        <cylinder length="0.4" radius="0.05"/>
      </geometry>
      <origin rpy="0 0 0" xyz="0 0 0.2"/>
    </collision>
    <inertial>
      <origin rpy="0 0 0" xyz="0 0 0"/>
      <mass value="0.5"/>
      <inertia ixx="0.006979166666666668" ixy="0.0" ixz="0.0" iyy="0.006979166666666668" iyz="0.0" izz="0.0006250000000000001"/>
    </inertial>
  </link>
  <!-- left arm link -->
  <link name="left_arm_link">
    <visual>
      <geometry>
        <cylinder length="0.5" radius="0.05"/>
      </geometry>
      <origin rpy="0 0 0" xyz="0 0 0.25"/>
      <material name="grey"/>
    </visual>
    <collision>
      <geometry>
        <cylinder length="0.5" radius="0.05"/>
      </geometry>
      <origin rpy="0 0 0" xyz="0 0 0.25"/>
    </collision>
    <inertial>
      <origin rpy="0 0 0" xyz="0 0 0"/>
      <mass value="0.5"/>
      <inertia ixx="0.006979166666666668" ixy="0.0" ixz="0.0" iyy="0.006979166666666668" iyz="0.0" izz="0.0006250000000000001"/>
    </inertial>
  </link>
  <joint name="body_shoulder_joint" type="revolute">
    <parent link="body_base_link"/>
    <child link="shoulder_link"/>
    <origin rpy="0 0 0" xyz="0 0 0.35"/>
    <axis xyz="0 0 1"/>
    <limit effort="100.0" lower="-1.57" upper="1.57" velocity="1.0"/>
  </joint>
  <joint name="shoulder_head_joint" type="fixed">
    <parent link="shoulder_link"/>
    <child link="head_link"/>
    <origin rpy="0 0 0" xyz="0 0.0 0.2"/>
  </joint>
  <joint name="right_hand_shoulder_joint" type="revolute">
    <parent link="shoulder_link"/>
    <child link="right_hand_link"/>
    <origin rpy="0 0 0" xyz="0 0.3 0.1"/>
    <axis xyz="0 1 0"/>
    <limit effort="100.0" lower="-1.57" upper="1.57" velocity="1.0"/>
  </joint>
  <joint name="right_hand_arm_joint" type="revolute">
    <parent link="right_hand_link"/>
    <child link="right_arm_link"/>
    <origin rpy="0 0 0" xyz="0 0 0.4"/>
    <axis xyz="0 1 0"/>
    <limit effort="100.0" lower="-1.57" upper="1.57" velocity="1.0"/>
  </joint>
  <joint name="left_hand_shoulder_joint" type="revolute">
    <parent link="shoulder_link"/>
    <child link="left_hand_link"/>
    <origin rpy="0 0 0" xyz="0 -0.3 0.1"/>
    <axis xyz="0 1 0"/>
    <limit effort="100.0" lower="-1.57" upper="1.57" velocity="1.0"/>
  </joint>
  <joint name="left_hand_arm_joint" type="revolute">
    <parent link="left_hand_link"/>
    <child link="left_arm_link"/>
    <origin rpy="0 0 0" xyz="0 0 0.4"/>
    <axis xyz="0 1 0"/>
    <limit effort="100.0" lower="-1.57" upper="1.57" velocity="1.0"/>
  </joint>
  <gazebo reference="body_base_link">
    <material>
            Gazebo/Red
        </material>
  </gazebo>
  <gazebo reference="shoulder_link">
    <material>
            Gazebo/Red
        </material>
  </gazebo>
  <gazebo reference="head_link">
    <material>
            Gazebo/Red
        </material>
  </gazebo>
  <gazebo reference="right_hand_link">
    <material>
            Gazebo/Red
        </material>
  </gazebo>
  <gazebo reference="right_arm_link">
    <material>
            Gazebo/Red
        </material>
  </gazebo>
  <gazebo reference="left_hand_link">
    <material>
            Gazebo/Red
        </material>
  </gazebo>
  <gazebo reference="left_arm_link">
    <material>
            Gazebo/Red
        </material>
  </gazebo>
  <link name="base_footprint"/>
  <link name="base_link">
    <visual>
      <geometry>
        <box size="0.6 0.4 0.2"/>
      </geometry>
      <origin rpy="0 0 0" xyz="0 0 0.1"/>
      <material name="blue"/>
    </visual>
    <collision>
      <geometry>
        <box size="0.6 0.4 0.2"/>
      </geometry>
      <origin rpy="0 0 0" xyz="0 0 0.1"/>
    </collision>
    <inertial>
      <origin rpy="0 0 0" xyz="0 0 0.1"/>
      <mass value="5.0"/>
      <inertia ixx="0.16666666666666669" ixy="0.0" ixz="0.0" iyy="0.21666666666666667" iyz="0.0" izz="0.08333333333333336"/>
    </inertial>
  </link>
  <link name="right_wheel_link">
    <visual>
      <geometry>
        <cylinder length="0.05" radius="0.1"/>
      </geometry>
      <origin rpy="1.5707963267948966 0 0" xyz="0 0 0"/>
      <material name="grey"/>
    </visual>
    <collision>
      <geometry>
        <cylinder length="0.05" radius="0.1"/>
      </geometry>
      <origin rpy="1.5707963267948966 0 0" xyz="0 0 0"/>
    </collision>
    <inertial>
      <origin rpy="1.5707963267948966 0 0" xyz="0 0 0"/>
      <mass value="1.0"/>
      <inertia ixx="0.002708333333333334" ixy="0.0" ixz="0.0" iyy="0.002708333333333334" iyz="0.0" izz="0.005000000000000001"/>
    </inertial>
  </link>
  <link name="left_wheel_link">
    <visual>
      <geometry>
        <cylinder length="0.05" radius="0.1"/>
      </geometry>
      <origin rpy="1.5707963267948966 0 0" xyz="0 0 0"/>
      <material name="grey"/>
    </visual>
    <collision>
      <geometry>
        <cylinder length="0.05" radius="0.1"/>
      </geometry>
      <origin rpy="1.5707963267948966 0 0" xyz="0 0 0"/>
    </collision>
    <inertial>
      <origin rpy="1.5707963267948966 0 0" xyz="0 0 0"/>
      <mass value="1.0"/>
      <inertia ixx="0.002708333333333334" ixy="0.0" ixz="0.0" iyy="0.002708333333333334" iyz="0.0" izz="0.005000000000000001"/>
    </inertial>
  </link>
  <link name="caster_wheel_link">
    <visual>
      <geometry>
        <sphere radius="0.05"/>
      </geometry>
      <origin rpy="0 0 0" xyz="0 0 0"/>
      <material name="grey"/>
    </visual>
    <collision>
      <geometry>
        <sphere radius="0.05"/>
      </geometry>
      <origin rpy="0 0 0" xyz="0 0 0"/>
    </collision>
    <inertial>
      <origin rpy="0 0 0" xyz="0 0 0"/>
      <mass value="0.5"/>
      <inertia ixx="0.0005000000000000001" ixy="0.0" ixz="0.0" iyy="0.0005000000000000001" iyz="0.0" izz="0.0005000000000000001"/>
    </inertial>
  </link>
  <joint name="base_joint" type="fixed">
    <parent link="base_footprint"/>
    <child link="base_link"/>
    <origin rpy="0 0 0" xyz="0 0 0.1"/>
  </joint>
  <joint name="wheel_right_joint" type="continuous">
    <parent link="base_link"/>
    <child link="right_wheel_link"/>
    <origin rpy="0 0 0" xyz="-0.15 -0.225 0"/>
    <axis xyz="0 1 0"/>
  </joint>
  <joint name="wheel_left_joint" type="continuous">
    <parent link="base_link"/>
    <child link="left_wheel_link"/>
    <origin rpy="0 0 0" xyz="-0.15 0.225 0"/>
    <axis xyz="0 1 0"/>
  </joint>
  <joint name="base_caster_wheel_joint" type="fixed">
    <parent link="base_link"/>
    <child link="caster_wheel_link"/>
    <origin rpy="0 0 0" xyz="0.19999999999999998 0 -0.05"/>
  </joint>
  <gazebo reference="base_link">
    <material>
            Gazebo/Blue
        </material>
  </gazebo>
  <gazebo reference="right_wheel_link">
    <material>
            Gazebo/Green
        </material>
  </gazebo>
  <gazebo reference="left_wheel_link">
    <material>
            Gazebo/Green
        </material>
  </gazebo>
  <gazebo reference="caster_wheel_link">
    <material>
            Gazebo/Red
        </material>
    <mu1 value="0.1"/>
    <mu2 value="0.1"/>
  </gazebo>
  <gazebo>
    <plugin filename="libgazebo_ros_diff_drive.so" name="diff_drive_controller">
      <!-- Update rate in Hz -->
      <update_rate>50</update_rate>
      <!-- wheels -->
      <left_joint>wheel_left_joint</left_joint>
      <right_joint>wheel_right_joint</right_joint>
      <!-- kinematics -->
      <wheel_separation>0.45</wheel_separation>
      <wheel_diameter>0.2</wheel_diameter>
      <!-- output -->
      <publish_odom>true</publish_odom>
      <publish_odom_tf>true</publish_odom_tf>
      <publish_wheel_tf>true</publish_wheel_tf>
      <odometry_topic>odom</odometry_topic>
      <odometry_frame>odom</odometry_frame>
      <robot_base_frame>base_link</robot_base_frame>
    </plugin>
  </gazebo>
  <!--camera link-->
  <link name="camera_link">
    <visual>
      <geometry>
        <box size="0.01 0.1 0.05"/>
      </geometry>
      <material name="blue"/>
    </visual>
    <collision>
      <geometry>
        <box size="0.01 0.1 0.05"/>
      </geometry>
    </collision>
    <inertial>
      <origin rpy="0 0 0" xyz="0 0 0"/>
      <mass value="0.1"/>
      <inertia ixx="2.166666666666667e-05" ixy="0.0" ixz="0.0" iyy="8.416666666666668e-05" iyz="0.0" izz="0.00010416666666666669"/>
    </inertial>
  </link>
  <joint name="head_camera_joint" type="fixed">
    <parent link="head_link"/>
    <child link="camera_link"/>
    <origin rpy="0 0 0" xyz="0.1 0 0"/>
  </joint>
  <gazebo reference="camera_link">
    <material>
            Gazebo/Blue
        </material>
    <sensor name="camera_sensor" type="camera">
      <pose>0 0 0 0 0 0</pose>
      <visualize>true</visualize>
      <update_rate>10.0</update_rate>
      <plugin filename="libgazebo_ros_camera.so" name="camera_controller">
        <frame_name>camera_link</frame_name>
      </plugin>
    </sensor>
  </gazebo>
  <!--camera link-->
  <link name="lidar_link">
    <visual>
      <geometry>
        <box size="0.01 0.1 0.05"/>
      </geometry>
      <material name="blue"/>
    </visual>
    <collision>
      <geometry>
        <box size="0.01 0.1 0.05"/>
      </geometry>
    </collision>
    <inertial>
      <origin rpy="0 1.57 0" xyz="0 0 0"/>
      <mass value="0.1"/>
      <inertia ixx="2.166666666666667e-05" ixy="0.0" ixz="0.0" iyy="8.416666666666668e-05" iyz="0.0" izz="0.00010416666666666669"/>
    </inertial>
  </link>
  <joint name="head_lidar_joint" type="fixed">
    <parent link="head_link"/>
    <child link="lidar_link"/>
    <origin rpy="0 0 0" xyz="0 0 0.1"/>
  </joint>
  <gazebo reference="lidar_link">
    <sensor name="lidar_sensor" type="ray">
      <pose>0 0 0 0 0 0</pose>
      <visualize>true</visualize>
      <!-- This enables visualization of the scan in Gazebo -->
      <update_rate>5</update_rate>
      <!-- Frequency of the scan -->
      <ray>
        <scan>
          <horizontal>
            <samples>720</samples>
            <!-- Number of scan points (angular resolution) -->
            <resolution>1</resolution>
            <min_angle>0</min_angle>
            <!-- Start scanning from -90 degrees -->
            <max_angle>6.28</max_angle>
            <!-- End scanning at +90 degrees -->
          </horizontal>
        </scan>
        <range>
          <min>0.2</min>
          <!-- Minimum range of the LiDAR -->
          <max>30.0</max>
          <!-- Maximum range of the LiDAR -->
        </range>
      </ray>
      <plugin filename="libgazebo_ros_ray_sensor.so" name="turtlebot3_laserscan">
        <output_type>sensor_msgs/LaserScan</output_type>
        <frame_name>lidar_link</frame_name>
      </plugin>
    </sensor>
  </gazebo>
  <!--camera link-->
  <link name="imu_link">
    <visual>
      <geometry>
        <box size="0.01 0.1 0.05"/>
      </geometry>
      <material name="blue"/>
    </visual>
    <collision>
      <geometry>
        <box size="0.01 0.1 0.05"/>
      </geometry>
    </collision>
    <inertial>
      <origin rpy="0 1.57 0" xyz="0 0 0"/>
      <mass value="0.1"/>
      <inertia ixx="2.166666666666667e-05" ixy="0.0" ixz="0.0" iyy="8.416666666666668e-05" iyz="0.0" izz="0.00010416666666666669"/>
    </inertial>
  </link>
  <joint name="base_imu_joint" type="fixed">
    <parent link="base_link"/>
    <child link="imu_link"/>
    <origin rpy="0 1.57 0" xyz="0.19999999999999998 0 0.2"/>
  </joint>
  <gazebo reference="imu_link">
    <sensor name="imu_sensor" type="imu">
      <!-- ensure the sensor is active (required) -->
      <always_on>true</always_on>
      <update_rate>30</update_rate>
      <plugin filename="libgazebo_ros_imu_sensor.so" name="my_imu_plugin">
        <ros>
          <remapping>~/out:=imu</remapping>
        </ros>
      </plugin>
    </sensor>
  </gazebo>
  <joint name="base_upper_joint" type="fixed">
    <parent link="base_link"/>
    <child link="body_base_link"/>
    <origin rpy="0 0 0" xyz="0.06 0 0.45"/>
  </joint>
</robot>
