<sdf version='1.7'>
  <model name='medibot'>
    <link name='base_footprint'>
      <inertial>
        <pose>0.038676 0 0.264706 0 -0 0</pose>
        <mass>6.8</mass>
        <inertia>
          <ixx>0.441344</ixx>
          <ixy>0</ixy>
          <ixz>-0.0357074</ixz>
          <iyy>0.522927</iyy>
          <iyz>0</iyz>
          <izz>0.125541</izz>
        </inertia>
      </inertial>
      <collision name='base_footprint_fixed_joint_lump__base_link_collision'>
        <pose>0 0 0.2 0 -0 0</pose>
        <geometry>
          <box>
            <size>0.6 0.4 0.2</size>
          </box>
        </geometry>
        <surface>
          <contact>
            <ode/>
          </contact>
          <friction>
            <ode/>
          </friction>
        </surface>
      </collision>
      <collision name='base_footprint_fixed_joint_lump__caster_wheel_link_collision_1'>
        <pose>0.2 0 0.05 0 -0 0</pose>
        <geometry>
          <sphere>
            <radius>0.05</radius>
          </sphere>
        </geometry>
        <surface>
          <contact>
            <ode/>
          </contact>
          <friction>
            <ode>
              <mu>0.1</mu>
              <mu2>0.1</mu2>
            </ode>
          </friction>
        </surface>
      </collision>
      <collision name='base_footprint_fixed_joint_lump__imu_link_collision_2'>
        <pose>0.2 0 0.3 0 1.5708 0</pose>
        <geometry>
          <box>
            <size>0.01 0.1 0.05</size>
          </box>
        </geometry>
        <surface>
          <contact>
            <ode/>
          </contact>
          <friction>
            <ode/>
          </friction>
        </surface>
      </collision>
      <collision name='base_footprint_fixed_joint_lump__base_scan_collision_3'>
        <pose>0.06 0 0.325 0 -0 0</pose>
        <geometry>
          <box>
            <size>0.01 0.1 0.05</size>
          </box>
        </geometry>
        <surface>
          <contact>
            <ode/>
          </contact>
          <friction>
            <ode/>
          </friction>
        </surface>
      </collision>
      <collision name='base_footprint_fixed_joint_lump__baymax_link_collision_4'>
        <pose>0.02 0 0.9 0 -0 1.57</pose>
        <geometry>
          <mesh>
            <scale>0.007 0.007 0.007</scale>
            <uri>file:///home/nabil/ros2_ws/src/medibot/urdf/Baymax.STL</uri>
          </mesh>
        </geometry>
      </collision>
      <collision name='base_footprint_fixed_joint_lump__camera_link_collision_5'>
        <pose>0.17 0 1.375 0 -0 0</pose>
        <geometry>
          <box>
            <size>0.01 0.1 0.05</size>
          </box>
        </geometry>
        <surface>
          <contact>
            <ode/>
          </contact>
          <friction>
            <ode/>
          </friction>
        </surface>
      </collision>
      <visual name='base_footprint_fixed_joint_lump__base_link_visual'>
        <pose>0 0 0.2 0 -0 0</pose>
        <geometry>
          <box>
            <size>0.6 0.4 0.2</size>
          </box>
        </geometry>
        <material>
          <script>
            <name>Gazebo/Blue</name>
            <uri>file://media/materials/scripts/gazebo.material</uri>
          </script>
        </material>
      </visual>
      <visual name='base_footprint_fixed_joint_lump__caster_wheel_link_visual_1'>
        <pose>0.2 0 0.05 0 -0 0</pose>
        <geometry>
          <sphere>
            <radius>0.05</radius>
          </sphere>
        </geometry>
        <material>
          <script>
            <name>Gazebo/Red</name>
            <uri>file://media/materials/scripts/gazebo.material</uri>
          </script>
        </material>
      </visual>
      <visual name='base_footprint_fixed_joint_lump__imu_link_visual_2'>
        <pose>0.2 0 0.3 0 1.5708 0</pose>
        <geometry>
          <box>
            <size>0.01 0.1 0.05</size>
          </box>
        </geometry>
      </visual>
      <visual name='base_footprint_fixed_joint_lump__base_scan_visual_3'>
        <pose>0.06 0 0.325 0 -0 0</pose>
        <geometry>
          <box>
            <size>0.01 0.1 0.05</size>
          </box>
        </geometry>
      </visual>
      <visual name='base_footprint_fixed_joint_lump__baymax_link_visual_4'>
        <pose>0.02 0 0.9 0 -0 1.57</pose>
        <geometry>
          <mesh>
            <scale>0.007 0.007 0.007</scale>
            <uri>file:///home/nabil/ros2_ws/src/medibot/urdf/Baymax.STL</uri>
          </mesh>
        </geometry>
      </visual>
      <visual name='base_footprint_fixed_joint_lump__camera_link_visual_5'>
        <pose>0.17 0 1.375 0 -0 0</pose>
        <geometry>
          <box>
            <size>0.01 0.1 0.05</size>
          </box>
        </geometry>
        <material>
          <script>
            <name>Gazebo/Blue</name>
            <uri>file://media/materials/scripts/gazebo.material</uri>
          </script>
        </material>
      </visual>
      <sensor name='imu_sensor' type='imu'>
        <always_on>1</always_on>
        <update_rate>30</update_rate>
        <plugin name='my_imu_plugin' filename='libgazebo_ros_imu_sensor.so'>
          <ros>
            <remapping>~/out:=imu</remapping>
          </ros>
        </plugin>
        <pose>0.2 0 0.3 3.14159 1.57079 3.14159</pose>
      </sensor>
      <sensor name='lidar_sensor' type='ray'>
        <visualize>1</visualize>
        <update_rate>5</update_rate>
        <ray>
          <scan>
            <horizontal>
              <samples>720</samples>
              <resolution>1</resolution>
              <min_angle>0</min_angle>
              <max_angle>6.28</max_angle>
            </horizontal>
          </scan>
          <range>
            <min>0.2</min>
            <max>30</max>
          </range>
        </ray>
        <plugin name='turtlebot3_laserscan' filename='libgazebo_ros_ray_sensor.so'>
          <ros>
            <remapping>/turtlebot3_laserscan/out:=/scan</remapping>
          </ros>
          <output_type>sensor_msgs/LaserScan</output_type>
          <frame_name>base_scan</frame_name>
          <topic>/scan</topic>
        </plugin>
        <pose>0.06 0 0.325 0 -0 0</pose>
      </sensor>
      <sensor name='camera_sensor' type='camera'>
        <visualize>1</visualize>
        <update_rate>10</update_rate>
        <plugin name='camera_controller' filename='libgazebo_ros_camera.so'>
          <frame_name>camera_link</frame_name>
        </plugin>
        <pose>0.17 0 1.375 0 -0 0</pose>
      </sensor>
    </link>
    <joint name='wheel_left_joint' type='revolute'>
      <pose relative_to='base_footprint'>-0.15 0.225 0.1 0 -0 0</pose>
      <parent>base_footprint</parent>
      <child>left_wheel_link</child>
      <axis>
        <xyz>0 1 0</xyz>
        <limit>
          <lower>-1e+16</lower>
          <upper>1e+16</upper>
        </limit>
        <dynamics>
          <spring_reference>0</spring_reference>
          <spring_stiffness>0</spring_stiffness>
        </dynamics>
      </axis>
    </joint>
    <link name='left_wheel_link'>
      <pose relative_to='wheel_left_joint'>0 0 0 0 -0 0</pose>
      <inertial>
        <pose>0 0 0 1.5708 -0 0</pose>
        <mass>1</mass>
        <inertia>
          <ixx>0.00270833</ixx>
          <ixy>0</ixy>
          <ixz>0</ixz>
          <iyy>0.00270833</iyy>
          <iyz>0</iyz>
          <izz>0.005</izz>
        </inertia>
      </inertial>
      <collision name='left_wheel_link_collision'>
        <pose>0 0 0 1.5708 -0 0</pose>
        <geometry>
          <cylinder>
            <length>0.05</length>
            <radius>0.1</radius>
          </cylinder>
        </geometry>
        <surface>
          <contact>
            <ode/>
          </contact>
          <friction>
            <ode/>
          </friction>
        </surface>
      </collision>
      <visual name='left_wheel_link_visual'>
        <pose>0 0 0 1.5708 -0 0</pose>
        <geometry>
          <cylinder>
            <length>0.05</length>
            <radius>0.1</radius>
          </cylinder>
        </geometry>
        <material>
          <script>
            <name>Gazebo/Green</name>
            <uri>file://media/materials/scripts/gazebo.material</uri>
          </script>
        </material>
      </visual>
    </link>
    <joint name='wheel_right_joint' type='revolute'>
      <pose relative_to='base_footprint'>-0.15 -0.225 0.1 0 -0 0</pose>
      <parent>base_footprint</parent>
      <child>right_wheel_link</child>
      <axis>
        <xyz>0 1 0</xyz>
        <limit>
          <lower>-1e+16</lower>
          <upper>1e+16</upper>
        </limit>
        <dynamics>
          <spring_reference>0</spring_reference>
          <spring_stiffness>0</spring_stiffness>
        </dynamics>
      </axis>
    </joint>
    <link name='right_wheel_link'>
      <pose relative_to='wheel_right_joint'>0 0 0 0 -0 0</pose>
      <inertial>
        <pose>0 0 0 1.5708 -0 0</pose>
        <mass>1</mass>
        <inertia>
          <ixx>0.00270833</ixx>
          <ixy>0</ixy>
          <ixz>0</ixz>
          <iyy>0.00270833</iyy>
          <iyz>0</iyz>
          <izz>0.005</izz>
        </inertia>
      </inertial>
      <collision name='right_wheel_link_collision'>
        <pose>0 0 0 1.5708 -0 0</pose>
        <geometry>
          <cylinder>
            <length>0.05</length>
            <radius>0.1</radius>
          </cylinder>
        </geometry>
        <surface>
          <contact>
            <ode/>
          </contact>
          <friction>
            <ode/>
          </friction>
        </surface>
      </collision>
      <visual name='right_wheel_link_visual'>
        <pose>0 0 0 1.5708 -0 0</pose>
        <geometry>
          <cylinder>
            <length>0.05</length>
            <radius>0.1</radius>
          </cylinder>
        </geometry>
        <material>
          <script>
            <name>Gazebo/Green</name>
            <uri>file://media/materials/scripts/gazebo.material</uri>
          </script>
        </material>
      </visual>
    </link>
    <static>0</static>
    <plugin name='diff_drive_controller' filename='libgazebo_ros_diff_drive.so'>
      <update_rate>50</update_rate>
      <left_joint>wheel_left_joint</left_joint>
      <right_joint>wheel_right_joint</right_joint>
      <wheel_separation>0.45</wheel_separation>
      <wheel_diameter>0.2</wheel_diameter>
      <publish_odom>1</publish_odom>
      <publish_odom_tf>1</publish_odom_tf>
      <publish_wheel_tf>1</publish_wheel_tf>
      <odometry_topic>odom</odometry_topic>
      <odometry_frame>odom</odometry_frame>
      <robot_base_frame>base_footprint</robot_base_frame>
    </plugin>
  </model>
</sdf>
